<!DOCTYPE html>
<html lang="en">
<head>
    <meta charset="UTF-8">
    <meta name="viewport" content="width=device-width, initial-scale=1.0">
    <meta http-equiv="X-UA-Compatible" content="ie=edge">
    <title>18.3 语法</title>
</head>
<body>
    <script>
        //async函数的语法规则总体上来说比较简单,难点是错误处理机制.
    
    //18.3.1 返回Promise对象
        //async函数返回一个Promise对象
        //async函数内部return语句返回的值,会成为then方法回调函数的参数
        async function f() {
            return 'hello world';
        }
        f().then((value) => console.log(value));    //hello world
        //上面的代码中,函数f内部return命令返回的值会被then方法回调函数接收到.
        
        //async函数内部抛出的错误会导致Promise对象变为reject状态
        //抛出的错误对象会被catch方法回调函数接收到

        async function ff() {
            throw new Error('出错了');
        }
        ff().then(
            v => console.log(v),
            e => console.log(e)
        )
        //Error:出错了

    //18.3.2 Promise对象的状态变化
        //async函数返回的Promise对象必须等到内部所有await命令右面的Promise对象执行完才会发生状态改变,
        //除非遇到return语句或者抛出错误.
        //也就是说,只有async函数内部的异步操作执行完,才会执行then方法指定的回调函数
        //下面是一个例子
        async function getTitle(url) {
            let response = await fetch(url);
            let html = await response.text();
            return html.match(/<title>([\s\S]+)<\/title>/i)[1];
        }
        getTitle('https://tc39.github.io/ecma262/').then(console.log)
        //上面的代码中,函数getTitle内部有3个操作:抓取页面,取出文本,匹配页面标题
        //只有这3个操作全部完成,才会执行then方法里面的console.log

    //18.3.3 await命令
        //正常情况下, await命令后面是一个Promise对象.
        //如果不是,会被转成一个立即resolve的Promise对象
        async function fo() {
            return await 123;
        }
        fo().then(v => console.log(v));   //123

        //上面的代码中,await命令的参数的数值123,它被转成Promise对象并立即resolve.
        //await命令后面的Promise对象如果变为reject状态,则reject的参数会被catch方法的回调函数接收到
        async function foo() {
            await Promise.reject('出错误了');
        }
        foo()
        .then(v => console.log(v))
        .catch(e => console.log(e));
        //出错了

        //上面的代码中,await语句前面没有return, 但是reject方法的参数依然传入了catch方法的回调函数.
        //这里如果在await前面加上return,效果是一样的
        //只要一个await语句后面的Promise变为reject,那么整个async函数都会中断执行.
        async function foo1() {
            await Promise.reject('出错了');
            await Promise.resolve('hello world');       //不会执行
        }
        //上面的代码中,第二个await语句是不会执行的,因为第一个await语句状态变成了reject
        //有时,我们希望即使前一个异步操作失败,也不要中断后面的异步操作.
        //这是可以将第一个await放在try...catch结构里面,这样不管这个异步操作是否成功,第二个await都会执行
        
        async function foo2() {
            try {
                await Promise.reject('error');
            } catch (error) {}
            return await Promise.resolve('hello world');
        }
        foo2().then(v => console.log(v));   //hello world
        
        //另一种方法是在await后面的Promise对象后添加一个catch方法,处理前面可能出现的错误
        async function foo3() {
            await Promise.reject('error')
                .catch(e => console.log(e));
            return await Promise.resolve('hello world');
        }
        foo3().then(v => console.log(v));
        //error
        //hello world
    //18.3.4 错误处理
        //如果await后面的异步操作出错,那么等同于async函数返回的Promise对象被reject
        async function foo4() {
            await new Promise((resolve, reject) => {
                throw new Error('error')
            })
        }
        foo4()
            .then(v => console.log(v))
            .catch(e => console.log(e))
        //error: error

        //上面的代码中,async函数foo4执行后,await后面的Promise对象会抛出一个错误对象,
        //导致catch方法的回调函数被调用,它的参数就是抛出错误对象.
        //具体的执行机制可以参考后文的'async函数的实现原理'
        //防止出错的方法也是将其放在try..catch代码块中
        async function foo5() {
            try {
                await new Promise(function (resolve, reject) {
                    throw new Error('出错了')
                })
            } catch (error) {
            }
            return await('hello world')
        }

        //如果有多个await命令,则可以统一放在try...catch结构中
        async function main() {
            try {
                var val1 = await firstStep();
                var val2 = await secondStep(val1);
                var val3 = await thirdStep(val2);
                console.log('final: ', val3);
            } catch(e) {
                console.log(e)
            }
        }
        //下面的例子使用try...catch结构,实现多次重复尝试
     /* const superagent = require('superagent');
        const NUM_PETRIES = 3;
        async function test() {
            for (let i = 0; i < NUM_PETRIES; i++) {
                try {
                    await superagent.get('http://google.com/this-throws-an-error');
                    break
                } catch (error) {
                }
            }
            console.log(i); 
        }
        test()
    */
        //上面的代码中,如果await操作成功,则会使用break语句退出循环
        //如果失败,则会被catch语句捕获,然后进入下一轮循环
    
    //18.3.5 使用注意点
        //第一点,前面已经说过,await命令后面的Promise对象的运行结果可能是rejected,
        //所以最好把await命令放在try...catch代码块中
        async function myFunction() {
            try {
                await somethingThatReturnsAPromise()
            } catch (error) {
                console.log(error);
            }
        }

        //另一种写法
        async function myFunction() {
            await somethingThatReturnsAPromise()
            .catch(err => console.log(err));
        }

        //第二点,多个await命令后面的异步操作如果不存在继发关系,最好让它们同时触发
        let f_oo = await getFoo();
        let bar = await getBar();
        //上面的代码中,getFoo和getBar是两个完全独立的异步操作(即互不依赖)被写成继发关系.
        //这样比较耗时,因为只有getFoo完成以后才会执行getBar,完全可以让它们同时触发

        //写法一
        let [foo, bar] = await Promise.all([getFoo(), getBar()])

        //写法二
        let fooPromise = getFoo();
        let barPromise = getBar();
        let foo = await fooPromsie;
        let bar = await barPromsie;
        //上面两种写法中,getFoo和getBar都是同时触发,这样就会缩短程序的执行时间,
        
        //第三点,await命令只能用在async函数之中,如果用在普通函数中会报错
        async function dbFunc(db) {
            let docs = [{}, {}, {}];

            //报错
            docs.forEach(function(doc) {
                await db.post(db)
            })
        }
        //上面的代码会报错,因为await用在普通函数之中.但是,如果将forEach方法的参数改成async函数,也会出现问题
        
        function dbFunc(db) {
            let docs = [{}, {}, {}];
            //可能得到错误结果
            docs.forEach(async function(doc) {
                await db.post(doc);
            })
        }

        //上面的代码可能不会正常工作,原因是这时的3个db.post操作将是并发进行,即同时执行,而不是继发执行.
        //正确的写法是采用for循环
        async function dbFunc(db) {
            let docs = [{}, {}, {}]
            
            for (let doc of docs) {
                await db.post(doc);
            }
        }

        //如果确实西方多个请求并发执行,可以使用Promsie.all方法,当3个请求都resolved时,下面两种写法的效果相同
        async function dbFunc(db) {
            let docs = [{}, {}, {}];
            let promises = docs.map(doc => db.post(doc));
            let results = await Promise.all(promises);
            console.log(results);
        }

        //或者使用下面的写法
        async function dbFunc(db) {
            let doc = [{}, {}, {}];
            let promises = docs.map(doc => db.post(doc));

            let result = [];
            for (let promise of promises) {
                result.push(await promise);
            }
            console.log(result);
        }
    </script>
</body>
</html>